# 프라미스와 에러 핸들링
프라미스가 거부되면 제어 흐름이 제일 가까운 rejection 핸들러로 넘어가기 때문에 프라미스 체인을 사용하면 에러를 쉽게 처리할 수 있다. 이는 실무에서 아주 유용한 기능이다.

`.catch`는 첫번째 핸들러일 필요가 없고 하나 이상의 `.then` 뒤에 올 수 있다.

예시:
```js
fetch('/article/promise-chaining/user.json')
  .then(response => response.json())
  .then(user => fetch(`https://api.github.com/users/${user.name}`))
  .then(response => response.json())
  .then(githubUser => new Promise((resolve, reject) => {
    let img = document.createElement('img');
    img.src = githubUser.avatar_url;
    img.className = 'promise-avatar-example';
    document.body.append(img);

    setTimeout(() => {
      img.remove();
      resolve(githubUser);
    }, 3000);
  }))
  .catch(error => alert(error.message));
```
네트워크 문제, 잘못된 형식의 JSON 등으로 인해 위쪽 프라미스 중 하나라도 거부되면 `.catch`에서 에러를 잡게 된다.

## 암시적 try…catch
프라미스 executor와 프라미스 핸들러 코드 주위에는 보이지 않는(암시적) `try..catch`가 있다. 예외가 발생하면 암시적 `try..catch`에서 예외를 잡고 이를 reject처럼 다룬다.
```js
new Promise((resolve, reject) => {
  throw new Error('에러 발생!');
}).catch(alert); // Error: 에러 발생!
```
위 예시는 아래 예시와 똑같이 동작한다.
```js
new Promise((resolve, reject) => {
  reject(new Error('에러 발생!'));
}).catch(alert); // Error: 에러 발생!
```
이런 일은 executor 함수뿐만 아니라 핸들러에서도 발생한다. `.then` 핸들러 안에서 `throw`를 사용해 에러를 던지면, 이 자체가 거부된 프라미스를 의미하게 된다. 따라서 제어 흐름이 가장 가까운 에러 핸들러로 넘어간다.

`throw`문이 만든 에러뿐만 아니라 모든 종류의 에러가 암시적 `try..catch`에서 처리된다.
```js
new Promise((resolve, reject) => {
  resolve('OK');
}).then((result) => {
  blabla(); // 존재하지 않는 함수
}).catch(alert); // ReferenceError: blabla is not defined
```

## 다시 던지기
일반 `try..catch`에서는 에러를 분석하고, 처리할 수 없는 에러라 판단되면 에러를 다시 던질 때가 있다. 프라미스에서도 유사한 일을 할 수 있다.

`.catch` 안에서 `throw`를 사용하면 제어 흐름이 가장 가까운 곳에 있는 에러 핸들러로 넘어간다. 여기서 에러가 성공적으로 처리되면 가장 가까운 곳에 있는 `.then` 핸들러로 제어 흐름이 넘어가 실행이 이어진다.

다음 예시의 `.catch`는 에러를 성공적으로 처리한다.
```js
// 실행 순서: catch -> then
new Promise((resolve, reject) => {
  throw new Error('에러 발생!');
}).catch(function(error) {
  alert('에러가 잘 처리되었습니다. 정상적으로 실행이 이어집니다.');
}).then(() => alert('다음 핸들러가 실행됩니다.'));
```
`.catch` 블록이 정상적으로 종료되었기 때문에 다음 성공 핸들러 `.then`이 호출되었다.

다음 예시에서는 첫 번째 `.catch` 블록에서 처리 못한 에러를 다시 던지고 있다.
```js run
// 실행 순서: catch -> catch
new Promise((resolve, reject) => {
  throw new Error('에러 발생!');
}).catch(function(error) { // (*)
  if (error instanceof URIError) {
    // 에러 처리
  } else {
    alert('처리할 수 없는 에러');
    
    throw error; // 에러 다시 던지기
  }
}).then(function() {
  /* 여기는 실행되지 않는다. */
}).catch(error => { // (**)
  alert(`알 수 없는 에러가 발생함: ${error}`);
  // 반환값이 없음 => 실행이 계속됨
});
```
실행 흐름이 첫 번째 `.catch`  `(*)`로 넘어갔다가 다음 `.catch`  `(**)`로 이어지는 것을 확인할 수 있다.

## 처리되지 못한 거부
다음 예시에서는 체인 끝에 `.catch`가 없기 때문에 에러를 처리할 수 없다.
```js
new Promise(function() {
  noSuchFunction(); // 존재하지 않는 함수를 호출하기 때문에 에러가 발생한다.
}).then(() => {
    // 성공상태의 프라미스를 처리하는 핸들러. 한 개 이상이 있을 수 있다.
}); // 끝에 .catch가 없다.
```
일반적인 에러가 발생하고 이를 `try..catch`에서 처리하지 못하는 경우, 스크립트가 죽고 콘솔 창에 메시지가 출력된다. 거부된 프라미스를 처리하지 못했을 때도 유사한 일이 발생한다.

자바스크립트 엔진은 프라미스 거부를 추적하다가 위와 같은 상황이 발생하면 전역 에러를 생성한다.

브라우저 환경에서는 이런 에러를 `unhandledrejection` 이벤트로 처리할 수 있다.
```js
window.addEventListener('unhandledrejection', function(event) {
  // unhandledrejection 이벤트에는 두 개의 특수 프로퍼티가 있다.
  alert(event.promise); // [object Promise]: 에러를 생성하는 프라미스
  alert(event.reason); // Error: 에러 발생!: 처리하지 못한 에러 객체
});

new Promise(function() {
  throw new Error("에러 발생!");
}); // 에러를 처리할 수 있는 .catch 핸들러가 없다.
```
`unhandledrejection` 이벤트는 [HTML 명세서](https://html.spec.whatwg.org/multipage/webappapis.html#unhandled-promise-rejections)에 정의된 표준 이벤트이다.

브라우저 환경에서는 에러가 발생했는데 `.catch`가 없으면 `unhandledrejection` 핸들러가 트리거된다. `unhandledrejection` 핸들러는 에러 정보가 담긴 `event` 객체를 받기 때문에 이 핸들러 안에서 원하는 작업을 할 수 있다.

대개 이런 에러는 회복할 수 없기 때문에 개발자로서 할 수 있는 최선의 방법은 사용자에게 문제 상황을 알리고 가능하다면 서버에 에러 정보를 보내는 것이다.

Node.js같은 기타 호스트 환경에도 처리하지 못한 에러를 다루는 방법을 여러 가지 제공한다.

## 요약
-   `.catch`  는 프라미스에서 발생한 모든 에러를 다룬다.  `reject()`가 호출되거나 에러가 던져지면  `.catch`에서 이를 처리한다.
-   `.catch`는 에러를 처리하고 싶은 지점에 정확히 위치시켜야 한다. 핸들러에서는 에러를 분석하고 알 수 없는 에러는 다시 던질 수 있다.
-   에러 발생 시, 회복할 방법이 없다면  `.catch`를 사용하지 않아도 된다.
-   `unhandledrejection`  이벤트 핸들러를 사용해 처리되지 않은 에러를 추적하고, 이를 사용자나 서버에게 알려서 애플리케이션이 아무런 설명도 없이 죽는 것을 방지할 수 있다.
